[2024-06-22T01:30:36.271+0000] {task_context_logger.py:104} ERROR - Executor reports task instance <TaskInstance: shopify_user.streaming_task scheduled__2024-06-21T00:00:00+00:00 [queued]> finished (failed) although the task says it's queued. (Info: None) Was the task killed externally?
